Workbook

Sheet Lista Movimenti
A1: Nome | B1: Categoria | C1: Importo | D1: Data | E1: Tipo
B2: ✈️ Viaggi/Vacanze | C2: 500 | D2: 46023 | E2: Risparmio
B3: 🌟 Altro extra | C3: 50 | D3: 46023 | E3: Risparmio
B4: 🍔 Cibo fuori | C4: 64 | D4: 46023 | E4: Spesa
B5: 🍲 Cibo/Spesa | C5: 125 | D5: 46023 | E5: Spesa
B6: 🎁 Regali | C6: 200 | D6: 46023 | E6: Spesa
B7: 🎫 Abbonamenti | C7: 9 | D7: 46023 | E7: Spesa
B8: 🎬 Intrattenimento | C8: 36 | D8: 46023 | E8: Spesa
B9: 🏋️ Palestra e affini | C9: 29 | D9: 46023 | E9: Spesa
B10: 🏠 Casa | C10: 230 | D10: 46023 | E10: Spesa
B11: 👕 Vestiti | C11: 112 | D11: 46023 | E11: Spesa
B12: 💅 Cura personale | C12: 100 | D12: 46023 | E12: Spesa
B13: 📚 Cultura | C13: 32 | D13: 46023 | E13: Spesa
B14: 📱 Telefono | C14: 12 | D14: 46023 | E14: Spesa
B15: 🤑 Stipendio | C15: 1500 | D15: 46023
B16: 🪙 Altre entrate | C16: 50 | D16: 46023
B17: 🚌 Trasporti | C17: 60 | D17: 46023 | E17: Spesa
B18: 🚑 Sanità | C18: 100 | D18: 46023 | E18: Spesa
B19: ✈️ Viaggi/Vacanze | C19: 200 | D19: 46054 | E19: Risparmio
B20: 🌟 Altro extra | C20: 112 | D20: 46054 | E20: Spesa
B21: 🍔 Cibo fuori | C21: 79 | D21: 46054 | E21: Spesa
B22: 🍲 Cibo/Spesa | D22: 46054
B23: 🎁 Regali | D23: 46054
B24: 🎫 Abbonamenti | D24: 46054
B25: 🎬 Intrattenimento | D25: 46054
B26: 🏋️ Palestra e affini | D26: 46054
B27: 🏠 Casa | C27: 780 | D27: 46054 | E27: Spesa
B28: 👕 Vestiti | D28: 46054
B29: 💅 Cura personale | D29: 46054
B30: 📚 Cultura | D30: 46054
B31: 📱 Telefono | D31: 46054
B32: 🤑 Stipendio | C32: 1400 | D32: 46054
B33: 🪙 Altre entrate | D33: 46054
B34: 🚌 Trasporti | D34: 46054
B35: 🚑 Sanità | D35: 46054
B36: ✈️ Viaggi/Vacanze | C36: 350 | D36: 46082 | E36: Spesa
B37: 🌟 Altro extra | D37: 46082
B38: 🍔 Cibo fuori | D38: 46082
B39: 🍲 Cibo/Spesa | D39: 46082
B40: 🎁 Regali | D40: 46082
...

Sheet ANNO
A3: Categoria | B3: Gennaio | C3: Febbraio | D3: Marzo | E3: Aprile | F3: Maggio | G3: Giugno | H3: Luglio | I3: Agosto | J3: Settembre | K3: Ottobre | L3: Novembre | M3: Dicembre | N3: Media | O3: Obiettivo | P3: Totale Annuo
A4: 🤑 Stipendio | B4: =SUMIFS('Lista Movimenti'!C:C, 'Lista Movimenti'!B:B, A4,'Lista Movimenti'!D:D, ">=01/01/2026", 'Lista Movimenti'!D:D, "<=31/01/2026") -> 1500 | C4: =SUMIFS('Lista Movimenti'!$C:$C, 'Lista Movimenti'!$B:$B, $A4, 'Lista Movimenti'!$D:$D, ">="&DATE(2026,2,1), 'Lista Movimenti'!$D:$D, "<="&DATE(2026,2,28)) -> 1400 | D4: =SUMIFS('Lista Movimenti'!$C:$C, 'Lista Movimenti'!$B:$B, $A4, 'Lista Movimenti'!$D:$D, ">="&DATE(2026,3,1), 'Lista Movimenti'!$D:$D, "<="&DATE(2026,3,31)) -> 1500 | E4: =SUMIFS('Lista Movimenti'!$C:$C, 'Lista Movimenti'!$B:$B, $A4, 'Lista Movimenti'!$D:$D, ">="&DATE(2026,4,1), 'Lista Movimenti'!$D:$D, "<="&DATE(2026,4,30)) -> 1300 | F4: =SUMIFS('Lista Movimenti'!$C:$C, 'Lista Movimenti'!$B:$B, $A4, 'Lista Movimenti'!$D:$D, ">="&DATE(2026,5,1), 'Lista Movimenti'!$D:$D, "<="&DATE(2026,5,31)) -> 1230 | G4: =SUMIFS('Lista Movimenti'!$C:$C, 'Lista Movimenti'!$B:$B, $A4, 'Lista Movimenti'!$D:$D, ">="&DATE(2026,6,1), 'Lista Movimenti'!$D:$D, "<="&DATE(2026,6,30)) -> 1450 | H4: =SUMIFS('Lista Movimenti'!$C:$C, 'Lista Movimenti'!$B:$B, $A4, 'Lista Movimenti'!$D:$D, ">="&DATE(2026,7,1), 'Lista Movimenti'!$D:$D, "<="&DATE(2026,7,31)) -> 1000 | I4: =SUMIFS('Lista Movimenti'!$C:$C, 'Lista Movimenti'!$B:$B, $A4, 'Lista Movimenti'!$D:$D, ">="&DATE(2026,8,1), 'Lista Movimenti'!$D:$D, "<="&DATE(2026,8,31)) -> 1250 | J4: =SUMIFS('Lista Movimenti'!$C:$C, 'Lista Movimenti'!$B:$B, $A4, 'Lista Movimenti'!$D:$D, ">="&DATE(2026,9,1), 'Lista Movimenti'!$D:$D, "<="&DATE(2026,9,30)) -> 1500 | K4: =SUMIFS('Lista Movimenti'!$C:$C, 'Lista Movimenti'!$B:$B, $A4, 'Lista Movimenti'!$D:$D, ">="&DATE(2026,10,1), 'Lista Movimenti'!$D:$D, "<="&DATE(2026,10,31)) -> 1600 | L4: =SUMIFS('Lista Movimenti'!$C:$C, 'Lista Movimenti'!$B:$B, $A4, 'Lista Movimenti'!$D:$D, ">="&DATE(2026,11,1), 'Lista Movimenti'!$D:$D, "<="&DATE(2026,11,30)) -> 1150 | M4: =SUMIFS('Lista Movimenti'!$C:$C, 'Lista Movimenti'!$B:$B, $A4, 'Lista Movimenti'!$D:$D, ">="&DATE(2026,12,1), 'Lista Movimenti'!$D:$D, "<="&DATE(2026,12,31)) -> 1450 | N4: =AVERAGE(B4:M4) -> 1360.8333 | P4: =SUM(B4:M4) -> 16330
A5: 🪙 Altre entrate | B5: =SUMIFS('Lista Movimenti'!C:C, 'Lista Movimenti'!B:B, A5,'Lista Movimenti'!D:D, ">=01/01/2026", 'Lista Movimenti'!D:D, "<=31/01/2026") -> 50 | C5: =SUMIFS('Lista Movimenti'!$C:$C, 'Lista Movimenti'!$B:$B, $A5, 'Lista Movimenti'!$D:$D, ">="&DATE(2026,2,1), 'Lista Movimenti'!$D:$D, "<="&DATE(2026,2,28)) -> 0 | D5: =SUMIFS('Lista Movimenti'!$C:$C, 'Lista Movimenti'!$B:$B, $A5, 'Lista Movimenti'!$D:$D, ">="&DATE(2026,3,1), 'Lista Movimenti'!$D:$D, "<="&DATE(2026,3,31)) -> 10 | E5: =SUMIFS('Lista Movimenti'!$C:$C, 'Lista Movimenti'!$B:$B, $A5, 'Lista Movimenti'!$D:$D, ">="&DATE(2026,4,1), 'Lista Movimenti'!$D:$D, "<="&DATE(2026,4,30)) -> 0 | F5: =SUMIFS('Lista Movimenti'!$C:$C, 'Lista Movimenti'!$B:$B, $A5, 'Lista Movimenti'!$D:$D, ">="&DATE(2026,5,1), 'Lista Movimenti'!$D:$D, "<="&DATE(2026,5,31)) -> 30 | G5: =SUMIFS('Lista Movimenti'!$C:$C, 'Lista Movimenti'!$B:$B, $A5, 'Lista Movimenti'!$D:$D, ">="&DATE(2026,6,1), 'Lista Movimenti'!$D:$D, "<="&DATE(2026,6,30)) -> 0 | H5: =SUMIFS('Lista Movimenti'!$C:$C, 'Lista Movimenti'!$B:$B, $A5, 'Lista Movimenti'!$D:$D, ">="&DATE(2026,7,1), 'Lista Movimenti'!$D:$D, "<="&DATE(2026,7,31)) -> 0 | I5: =SUMIFS('Lista Movimenti'!$C:$C, 'Lista Movimenti'!$B:$B, $A5, 'Lista Movimenti'!$D:$D, ">="&DATE(2026,8,1), 'Lista Movimenti'!$D:$D, "<="&DATE(2026,8,31)) -> 60 | J5: =SUMIFS('Lista Movimenti'!$C:$C, 'Lista Movimenti'!$B:$B, $A5, 'Lista Movimenti'!$D:$D, ">="&DATE(2026,9,1), 'Lista Movimenti'!$D:$D, "<="&DATE(2026,9,30)) -> 0 | K5: =SUMIFS('Lista Movimenti'!$C:$C, 'Lista Movimenti'!$B:$B, $A5, 'Lista Movimenti'!$D:$D, ">="&DATE(2026,10,1), 'Lista Movimenti'!$D:$D, "<="&DATE(2026,10,31)) -> 20 | L5: =SUMIFS('Lista Movimenti'!$C:$C, 'Lista Movimenti'!$B:$B, $A5, 'Lista Movimenti'!$D:$D, ">="&DATE(2026,11,1), 'Lista Movimenti'!$D:$D, "<="&DATE(2026,11,30)) -> 0 | M5: =SUMIFS('Lista Movimenti'!$C:$C, 'Lista Movimenti'!$B:$B, $A5, 'Lista Movimenti'!$D:$D, ">="&DATE(2026,12,1), 'Lista Movimenti'!$D:$D, "<="&DATE(2026,12,31)) -> 0 | N5: =AVERAGE(B5:M5) -> 14.166667 | P5: =SUM(B5:M5) -> 170
B6: =SUMIFS('Lista Movimenti'!C:C, 'Lista Movimenti'!B:B, A6,'Lista Movimenti'!D:D, ">=01/01/2026", 'Lista Movimenti'!D:D, "<=31/01/2026") -> 0 | C6: =SUMIFS('Lista Movimenti'!$C:$C, 'Lista Movimenti'!$B:$B, $A6, 'Lista Movimenti'!$D:$D, ">="&DATE(2026,2,1), 'Lista Movimenti'!$D:$D, "<="&DATE(2026,2,28)) -> 0 | D6: =SUMIFS('Lista Movimenti'!$C:$C, 'Lista Movimenti'!$B:$B, $A6, 'Lista Movimenti'!$D:$D, ">="&DATE(2026,3,1), 'Lista Movimenti'!$D:$D, "<="&DATE(2026,3,31)) -> 0 | E6: =SUMIFS('Lista Movimenti'!$C:$C, 'Lista Movimenti'!$B:$B, $A6, 'Lista Movimenti'!$D:$D, ">="&DATE(2026,4,1), 'Lista Movimenti'!$D:$D, "<="&DATE(2026,4,30)) -> 0 | F6: =SUMIFS('Lista Movimenti'!$C:$C, 'Lista Movimenti'!$B:$B, $A6, 'Lista Movimenti'!$D:$D, ">="&DATE(2026,5,1), 'Lista Movimenti'!$D:$D, "<="&DATE(2026,5,31)) -> 0 | G6: =SUMIFS('Lista Movimenti'!$C:$C, 'Lista Movimenti'!$B:$B, $A6, 'Lista Movimenti'!$D:$D, ">="&DATE(2026,6,1), 'Lista Movimenti'!$D:$D, "<="&DATE(2026,6,30)) -> 0 | H6: =SUMIFS('Lista Movimenti'!$C:$C, 'Lista Movimenti'!$B:$B, $A6, 'Lista Movimenti'!$D:$D, ">="&DATE(2026,7,1), 'Lista Movimenti'!$D:$D, "<="&DATE(2026,7,31)) -> 0 | I6: =SUMIFS('Lista Movimenti'!$C:$C, 'Lista Movimenti'!$B:$B, $A6, 'Lista Movimenti'!$D:$D, ">="&DATE(2026,8,1), 'Lista Movimenti'!$D:$D, "<="&DATE(2026,8,31)) -> 0 | J6: =SUMIFS('Lista Movimenti'!$C:$C, 'Lista Movimenti'!$B:$B, $A6, 'Lista Movimenti'!$D:$D, ">="&DATE(2026,9,1), 'Lista Movimenti'!$D:$D, "<="&DATE(2026,9,30)) -> 0 | K6: =SUMIFS('Lista Movimenti'!$C:$C, 'Lista Movimenti'!$B:$B, $A6, 'Lista Movimenti'!$D:$D, ">="&DATE(2026,10,1), 'Lista Movimenti'!$D:$D, "<="&DATE(2026,10,31)) -> 0 | L6: =SUMIFS('Lista Movimenti'!$C:$C, 'Lista Movimenti'!$B:$B, $A6, 'Lista Movimenti'!$D:$D, ">="&DATE(2026,11,1), 'Lista Movimenti'!$D:$D, "<="&DATE(2026,11,30)) -> 0 | M6: =SUMIFS('Lista Movimenti'!$C:$C, 'Lista Movimenti'!$B:$B, $A6, 'Lista Movimenti'!$D:$D, ">="&DATE(2026,12,1), 'Lista Movimenti'!$D:$D, "<="&DATE(2026,12,31)) -> 0 | N6: =AVERAGE(B6:M6) -> 0 | P6: =SUM(B6:M6) -> 0
B7: =SUMIFS('Lista Movimenti'!C:C, 'Lista Movimenti'!B:B, A7,'Lista Movimenti'!D:D, ">=01/01/2026", 'Lista Movimenti'!D:D, "<=31/01/2026") -> 0 | C7: =SUMIFS('Lista Movimenti'!$C:$C, 'Lista Movimenti'!$B:$B, $A7, 'Lista Movimenti'!$D:$D, ">="&DATE(2026,2,1), 'Lista Movimenti'!$D:$D, "<="&DATE(2026,2,28)) -> 0 | D7: =SUMIFS('Lista Movimenti'!$C:$C, 'Lista Movimenti'!$B:$B, $A7, 'Lista Movimenti'!$D:$D, ">="&DATE(2026,3,1), 'Lista Movimenti'!$D:$D, "<="&DATE(2026,3,31)) -> 0 | E7: =SUMIFS('Lista Movimenti'!$C:$C, 'Lista Movimenti'!$B:$B, $A7, 'Lista Movimenti'!$D:$D, ">="&DATE(2026,4,1), 'Lista Movimenti'!$D:$D, "<="&DATE(2026,4,30)) -> 0 | F7: =SUMIFS('Lista Movimenti'!$C:$C, 'Lista Movimenti'!$B:$B, $A7, 'Lista Movimenti'!$D:$D, ">="&DATE(2026,5,1), 'Lista Movimenti'!$D:$D, "<="&DATE(2026,5,31)) -> 0 | G7: =SUMIFS('Lista Movimenti'!$C:$C, 'Lista Movimenti'!$B:$B, $A7, 'Lista Movimenti'!$D:$D, ">="&DATE(2026,6,1), 'Lista Movimenti'!$D:$D, "<="&DATE(2026,6,30)) -> 0 | H7: =SUMIFS('Lista Movimenti'!$C:$C, 'Lista Movimenti'!$B:$B, $A7, 'Lista Movimenti'!$D:$D, ">="&DATE(2026,7,1), 'Lista Movimenti'!$D:$D, "<="&DATE(2026,7,31)) -> 0 | I7: =SUMIFS('Lista Movimenti'!$C:$C, 'Lista Movimenti'!$B:$B, $A7, 'Lista Movimenti'!$D:$D, ">="&DATE(2026,8,1), 'Lista Movimenti'!$D:$D, "<="&DATE(2026,8,31)) -> 0 | J7: =SUMIFS('Lista Movimenti'!$C:$C, 'Lista Movimenti'!$B:$B, $A7, 'Lista Movimenti'!$D:$D, ">="&DATE(2026,9,1), 'Lista Movimenti'!$D:$D, "<="&DATE(2026,9,30)) -> 0 | K7: =SUMIFS('Lista Movimenti'!$C:$C, 'Lista Movimenti'!$B:$B, $A7, 'Lista Movimenti'!$D:$D, ">="&DATE(2026,10,1), 'Lista Movimenti'!$D:$D, "<="&DATE(2026,10,31)) -> 0 | L7: =SUMIFS('Lista Movimenti'!$C:$C, 'Lista Movimenti'!$B:$B, $A7, 'Lista Movimenti'!$D:$D, ">="&DATE(2026,11,1), 'Lista Movimenti'!$D:$D, "<="&DATE(2026,11,30)) -> 0 | M7: =SUMIFS('Lista Movimenti'!$C:$C, 'Lista Movimenti'!$B:$B, $A7, 'Lista Movimenti'!$D:$D, ">="&DATE(2026,12,1), 'Lista Movimenti'!$D:$D, "<="&DATE(2026,12,31)) -> 0 | N7: =AVERAGE(B7:M7) -> 0 | P7: =SUM(B7:M7) -> 0
A8: Totale Entrate | B8: =SUM(Entrate_Anno[Gennaio]) -> 1550 | C8: =SUM(C4:C7) -> 1400 | D8: =SUM(D4:D7) -> 1510 | E8: =SUM(E4:E7) -> 1300 | F8: =SUM(F4:F7) -> 1260 | G8: =SUM(G4:G7) -> 1450 | H8: =SUM(H4:H7) -> 1000 | I8: =SUM(I4:I7) -> 1310 | J8: =SUM(J4:J7) -> 1500 | ... M8: =SUM(M4:M7) -> 1450 | N8: =AVERAGE(B8:M8) -> 1375 | P8: =SUM(Entrate_Anno[Totale Annuo]) -> 16500
A12: Necessita | B12: Categoria | C12: Gennaio | D12: Febbraio | E12: Marzo | F12: Aprile | G12: Maggio | H12: Giugno | I12: Luglio | J12: Agosto | K12: Settembre | L12: Ottobre | M12: Novembre | N12: Dicembre | O12: Media | P12: Obiettivo | Q12: Totale Annuo
B13: 🏠 Casa | C13: =SUMIFS('Lista Movimenti'!$C:$C, 'Lista Movimenti'!$B:$B, $B13, 'Lista Movimenti'!$E:$E, "Spesa", 'Lista Movimenti'!$D:$D, ">=01/01/2026", 'Lista Movimenti'!$D:$D, "<=31/01/2026") -> 230 | D13: =SUMIFS('Lista Movimenti'!$C:$C, 'Lista Movimenti'!$B:$B, $B13, 'Lista Movimenti'!$E:$E, "Spesa", 'Lista Movimenti'!$D:$D, ">=01/02/2026", 'Lista Movimenti'!$D:$D, "<=28/02/2026") -> 780 | E13: =SUMIFS('Lista Movimenti'!$C:$C, 'Lista Movimenti'!$B:$B, $B13, 'Lista Movimenti'!$E:$E, "Spesa", 'Lista Movimenti'!$D:$D, ">=01/03/2026", 'Lista Movimenti'!$D:$D, "<=31/03/2026") -> 0 | F13: =SUMIFS('Lista Movimenti'!$C:$C, 'Lista Movimenti'!$B:$B, $B13, 'Lista Movimenti'!$E:$E, "Spesa", 'Lista Movimenti'!$D:$D, ">=01/04/2026", 'Lista Movimenti'!$D:$D, "<=30/04/2026") -> 0 | G13: =SUMIFS('Lista Movimenti'!$C:$C, 'Lista Movimenti'!$B:$B, $B13, 'Lista Movimenti'!$E:$E, "Spesa", 'Lista Movimenti'!$D:$D, ">=01/05/2026", 'Lista Movimenti'!$D:$D, "<=31/05/2026") -> 0 | H13: =SUMIFS('Lista Movimenti'!$C:$C, 'Lista Movimenti'!$B:$B, $B13, 'Lista Movimenti'!$E:$E, "Spesa", 'Lista Movimenti'!$D:$D, ">=01/06/2026", 'Lista Movimenti'!$D:$D, "<=30/06/2026") -> 0 | I13: =SUMIFS('Lista Movimenti'!$C:$C, 'Lista Movimenti'!$B:$B, $B13, 'Lista Movimenti'!$E:$E, "Spesa", 'Lista Movimenti'!$D:$D, ">=01/07/2026", 'Lista Movimenti'!$D:$D, "<=31/07/2026") -> 399 | J13: =SUMIFS('Lista Movimenti'!$C:$C, 'Lista Movimenti'!$B:$B, $B13, 'Lista Movimenti'!$E:$E, "Spesa", 'Lista Movimenti'!$D:$D, ">=01/08/2026", 'Lista Movimenti'!$D:$D, "<=31/08/2026") -> 0 | K13: =SUMIFS('Lista Movimenti'!$C:$C, 'Lista Movimenti'!$B:$B, $B13, 'Lista Movimenti'!$E:$E, "Spesa", 'Lista Movimenti'!$D:$D, ">=01/09/2026", 'Lista Movimenti'!$D:$D, "<=30/09/2026") -> 0 | L13: =SUMIFS('Lista Movimenti'!$C:$C, 'Lista Movimenti'!$B:$B, $B13, 'Lista Movimenti'!$E:$E, "Spesa", 'Lista Movimenti'!$D:$D, ">=01/10/2026", 'Lista Movimenti'!$D:$D, "<=31/10/2026") -> 0 | M13: =SUMIFS('Lista Movimenti'!$C:$C, 'Lista Movimenti'!$B:$B, $B13, 'Lista Movimenti'!$E:$E, "Spesa", 'Lista Movimenti'!$D:$D, ">=01/11/2026", 'Lista Movimenti'!$D:$D, "<=30/11/2026") -> 200 | N13: =SUMIFS('Lista Movimenti'!$C:$C, 'Lista Movimenti'!$B:$B, $B13, 'Lista Movimenti'!$E:$E, "Spesa", 'Lista Movimenti'!$D:$D, ">=01/12/2026", 'Lista Movimenti'!$D:$D, "<=31/12/2026") -> 0 | O13: =AVERAGE(C13:N13) -> 134.08333 | P13: 200 | Q13: =SUM(C13:N13) -> 1609
B14: 🍲 Cibo/Spesa | C14: =SUMIFS('Lista Movimenti'!C:C, 'Lista Movimenti'!B:B, B14, 'Lista Movimenti'!E:E, "Spesa", 'Lista Movimenti'!D:D, ">=01/01/2026", 'Lista Movimenti'!D:D, "<=31/01/2026") -> 125 | D14: =SUMIFS('Lista Movimenti'!$C:$C, 'Lista Movimenti'!$B:$B, $B14, 'Lista Movimenti'!$E:$E, "Spesa", 'Lista Movimenti'!$D:$D, ">=01/02/2026", 'Lista Movimenti'!$D:$D, "<=28/02/2026") -> 0 | E14: =SUMIFS('Lista Movimenti'!$C:$C, 'Lista Movimenti'!$B:$B, $B14, 'Lista Movimenti'!$E:$E, "Spesa", 'Lista Movimenti'!$D:$D, ">=01/03/2026", 'Lista Movimenti'!$D:$D, "<=31/03/2026") -> 0 | F14: =SUMIFS('Lista Movimenti'!$C:$C, 'Lista Movimenti'!$B:$B, $B14, 'Lista Movimenti'!$E:$E, "Spesa", 'Lista Movimenti'!$D:$D, ">=01/04/2026", 'Lista Movimenti'!$D:$D, "<=30/04/2026") -> 300 | G14: =SUMIFS('Lista Movimenti'!$C:$C, 'Lista Movimenti'!$B:$B, $B14, 'Lista Movimenti'!$E:$E, "Spesa", 'Lista Movimenti'!$D:$D, ">=01/05/2026", 'Lista Movimenti'!$D:$D, "<=31/05/2026") -> 0 | H14: =SUMIFS('Lista Movimenti'!$C:$C, 'Lista Movimenti'!$B:$B, $B14, 'Lista Movimenti'!$E:$E, "Spesa", 'Lista Movimenti'!$D:$D, ">=01/06/2026", 'Lista Movimenti'!$D:$D, "<=30/06/2026") -> 0 | I14: =SUMIFS('Lista Movimenti'!$C:$C, 'Lista Movimenti'!$B:$B, $B14, 'Lista Movimenti'!$E:$E, "Spesa", 'Lista Movimenti'!$D:$D, ">=01/07/2026", 'Lista Movimenti'!$D:$D, "<=31/07/2026") -> 200 | J14: =SUMIFS('Lista Movimenti'!$C:$C, 'Lista Movimenti'!$B:$B, $B14, 'Lista Movimenti'!$E:$E, "Spesa", 'Lista Movimenti'!$D:$D, ">=01/08/2026", 'Lista Movimenti'!$D:$D, "<=31/08/2026") -> 0 | K14: =SUMIFS('Lista Movimenti'!$C:$C, 'Lista Movimenti'!$B:$B, $B14, 'Lista Movimenti'!$E:$E, "Spesa", 'Lista Movimenti'!$D:$D, ">=01/09/2026", 'Lista Movimenti'!$D:$D, "<=30/09/2026") -> 0 | L14: =SUMIFS('Lista Movimenti'!$C:$C, 'Lista Movimenti'!$B:$B, $B14, 'Lista Movimenti'!$E:$E, "Spesa", 'Lista Movimenti'!$D:$D, ">=01/10/2026", 'Lista Movimenti'!$D:$D, "<=31/10/2026") -> 100 | M14: =SUMIFS('Lista Movimenti'!$C:$C, 'Lista Movimenti'!$B:$B, $B14, 'Lista Movimenti'!$E:$E, "Spesa", 'Lista Movimenti'!$D:$D, ">=01/11/2026", 'Lista Movimenti'!$D:$D, "<=30/11/2026") -> 0 | N14: =SUMIFS('Lista Movimenti'!$C:$C, 'Lista Movimenti'!$B:$B, $B14, 'Lista Movimenti'!$E:$E, "Spesa", 'Lista Movimenti'!$D:$D, ">=01/12/2026", 'Lista Movimenti'!$D:$D, "<=31/12/2026") -> 0 | O14: =AVERAGE(C14:N14) -> 60.416667 | P14: 280 | Q14: =SUM(C14:N14) -> 725
B15: 🚑 Sanità | C15: =SUMIFS('Lista Movimenti'!C:C, 'Lista Movimenti'!B:B, B15, 'Lista Movimenti'!E:E, "Spesa", 'Lista Movimenti'!D:D, ">=01/01/2026", 'Lista Movimenti'!D:D, "<=31/01/2026") -> 100 | D15: =SUMIFS('Lista Movimenti'!$C:$C, 'Lista Movimenti'!$B:$B, $B15, 'Lista Movimenti'!$E:$E, "Spesa", 'Lista Movimenti'!$D:$D, ">=01/02/2026", 'Lista Movimenti'!$D:$D, "<=28/02/2026") -> 0 | E15: =SUMIFS('Lista Movimenti'!$C:$C, 'Lista Movimenti'!$B:$B, $B15, 'Lista Movimenti'!$E:$E, "Spesa", 'Lista Movimenti'!$D:$D, ">=01/03/2026", 'Lista Movimenti'!$D:$D, "<=31/03/2026") -> 0 | F15: =SUMIFS('Lista Movimenti'!$C:$C, 'Lista Movimenti'!$B:$B, $B15, 'Lista Movimenti'!$E:$E, "Spesa", 'Lista Movimenti'!$D:$D, ">=01/04/2026", 'Lista Movimenti'!$D:$D, "<=30/04/2026") -> 0 | G15: =SUMIFS('Lista Movimenti'!$C:$C, 'Lista Movimenti'!$B:$B, $B15, 'Lista Movimenti'!$E:$E, "Spesa", 'Lista Movimenti'!$D:$D, ">=01/05/2026", 'Lista Movimenti'!$D:$D, "<=31/05/2026") -> 0 | H15: =SUMIFS('Lista Movimenti'!$C:$C, 'Lista Movimenti'!$B:$B, $B15, 'Lista Movimenti'!$E:$E, "Spesa", 'Lista Movimenti'!$D:$D, ">=01/06/2026", 'Lista Movimenti'!$D:$D, "<=30/06/2026") -> 0 | I15: =SUMIFS('Lista Movimenti'!$C:$C, 'Lista Movimenti'!$B:$B, $B15, 'Lista Movimenti'!$E:$E, "Spesa", 'Lista Movimenti'!$D:$D, ">=01/07/2026", 'Lista Movimenti'!$D:$D, "<=31/07/2026") -> 0 | J15: =SUMIFS('Lista Movimenti'!$C:$C, 'Lista Movimenti'!$B:$B, $B15, 'Lista Movimenti'!$E:$E, "Spesa", 'Lista Movimenti'!$D:$D, ">=01/08/2026", 'Lista Movimenti'!$D:$D, "<=31/08/2026") -> 0 | K15: =SUMIFS('Lista Movimenti'!$C:$C, 'Lista Movimenti'!$B:$B, $B15, 'Lista Movimenti'!$E:$E, "Spesa", 'Lista Movimenti'!$D:$D, ">=01/09/2026", 'Lista Movimenti'!$D:$D, "<=30/09/2026") -> 0 | L15: =SUMIFS('Lista Movimenti'!$C:$C, 'Lista Movimenti'!$B:$B, $B15, 'Lista Movimenti'!$E:$E, "Spesa", 'Lista Movimenti'!$D:$D, ">=01/10/2026", 'Lista Movimenti'!$D:$D, "<=31/10/2026") -> 0 | M15: =SUMIFS('Lista Movimenti'!$C:$C, 'Lista Movimenti'!$B:$B, $B15, 'Lista Movimenti'!$E:$E, "Spesa", 'Lista Movimenti'!$D:$D, ">=01/11/2026", 'Lista Movimenti'!$D:$D, "<=30/11/2026") -> 0 | N15: =SUMIFS('Lista Movimenti'!$C:$C, 'Lista Movimenti'!$B:$B, $B15, 'Lista Movimenti'!$E:$E, "Spesa", 'Lista Movimenti'!$D:$D, ">=01/12/2026", 'Lista Movimenti'!$D:$D, "<=31/12/2026") -> 0 | O15: =AVERAGE(C15:N15) -> 8.3333333 | P15: 50 | Q15: =SUM(C15:N15) -> 100
B16: 🏋️ Palestra e affini | C16: =SUMIFS('Lista Movimenti'!C:C, 'Lista Movimenti'!B:B, B16, 'Lista Movimenti'!E:E, "Spesa", 'Lista Movimenti'!D:D, ">=01/01/2026", 'Lista Movimenti'!D:D, "<=31/01/2026") -> 29 | D16: =SUMIFS('Lista Movimenti'!$C:$C, 'Lista Movimenti'!$B:$B, $B16, 'Lista Movimenti'!$E:$E, "Spesa", 'Lista Movimenti'!$D:$D, ">=01/02/2026", 'Lista Movimenti'!$D:$D, "<=28/02/2026") -> 0 | E16: =SUMIFS('Lista Movimenti'!$C:$C, 'Lista Movimenti'!$B:$B, $B16, 'Lista Movimenti'!$E:$E, "Spesa", 'Lista Movimenti'!$D:$D, ">=01/03/2026", 'Lista Movimenti'!$D:$D, "<=31/03/2026") -> 0 | F16: =SUMIFS('Lista Movimenti'!$C:$C, 'Lista Movimenti'!$B:$B, $B16, 'Lista Movimenti'!$E:$E, "Spesa", 'Lista Movimenti'!$D:$D, ">=01/04/2026", 'Lista Movimenti'!$D:$D, "<=30/04/2026") -> 0 | G16: =SUMIFS('Lista Movimenti'!$C:$C, 'Lista Movimenti'!$B:$B, $B16, 'Lista Movimenti'!$E:$E, "Spesa", 'Lista Movimenti'!$D:$D, ">=01/05/2026", 'Lista Movimenti'!$D:$D, "<=31/05/2026") -> 0 | H16: =SUMIFS('Lista Movimenti'!$C:$C, 'Lista Movimenti'!$B:$B, $B16, 'Lista Movimenti'!$E:$E, "Spesa", 'Lista Movimenti'!$D:$D, ">=01/06/2026", 'Lista Movimenti'!$D:$D, "<=30/06/2026") -> 0 | I16: =SUMIFS('Lista Movimenti'!$C:$C, 'Lista Movimenti'!$B:$B, $B16, 'Lista Movimenti'!$E:$E, "Spesa", 'Lista Movimenti'!$D:$D, ">=01/07/2026", 'Lista Movimenti'!$D:$D, "<=31/07/2026") -> 0 | J16: =SUMIFS('Lista Movimenti'!$C:$C, 'Lista Movimenti'!$B:$B, $B16, 'Lista Movimenti'!$E:$E, "Spesa", 'Lista Movimenti'!$D:$D, ">=01/08/2026", 'Lista Movimenti'!$D:$D, "<=31/08/2026") -> 55 | K16: =SUMIFS('Lista Movimenti'!$C:$C, 'Lista Movimenti'!$B:$B, $B16, 'Lista Movimenti'!$E:$E, "Spesa", 'Lista Movimenti'!$D:$D, ">=01/09/2026", 'Lista Movimenti'!$D:$D, "<=30/09/2026") -> 0 | L16: =SUMIFS('Lista Movimenti'!$C:$C, 'Lista Movimenti'!$B:$B, $B16, 'Lista Movimenti'!$E:$E, "Spesa", 'Lista Movimenti'!$D:$D, ">=01/10/2026", 'Lista Movimenti'!$D:$D, "<=31/10/2026") -> 0 | M16: =SUMIFS('Lista Movimenti'!$C:$C, 'Lista Movimenti'!$B:$B, $B16, 'Lista Movimenti'!$E:$E, "Spesa", 'Lista Movimenti'!$D:$D, ">=01/11/2026", 'Lista Movimenti'!$D:$D, "<=30/11/2026") -> 0 | N16: =SUMIFS('Lista Movimenti'!$C:$C, 'Lista Movimenti'!$B:$B, $B16, 'Lista Movimenti'!$E:$E, "Spesa", 'Lista Movimenti'!$D:$D, ">=01/12/2026", 'Lista Movimenti'!$D:$D, "<=31/12/2026") -> 45 | O16: =AVERAGE(C16:N16) -> 10.75 | P16: 40 | Q16: =SUM(C16:N16) -> 129
B17: 📱 Telefono | C17: =SUMIFS('Lista Movimenti'!C:C, 'Lista Movimenti'!B:B, B17, 'Lista Movimenti'!E:E, "Spesa", 'Lista Movimenti'!D:D, ">=01/01/2026", 'Lista Movimenti'!D:D, "<=31/01/2026") -> 12 | D17: =SUMIFS('Lista Movimenti'!$C:$C, 'Lista Movimenti'!$B:$B, $B17, 'Lista Movimenti'!$E:$E, "Spesa", 'Lista Movimenti'!$D:$D, ">=01/02/2026", 'Lista Movimenti'!$D:$D, "<=28/02/2026") -> 0 | E17: =SUMIFS('Lista Movimenti'!$C:$C, 'Lista Movimenti'!$B:$B, $B17, 'Lista Movimenti'!$E:$E, "Spesa", 'Lista Movimenti'!$D:$D, ">=01/03/2026", 'Lista Movimenti'!$D:$D, "<=31/03/2026") -> 0 | F17: =SUMIFS('Lista Movimenti'!$C:$C, 'Lista Movimenti'!$B:$B, $B17, 'Lista Movimenti'!$E:$E, "Spesa", 'Lista Movimenti'!$D:$D, ">=01/04/2026", 'Lista Movimenti'!$D:$D, "<=30/04/2026") -> 0 | G17: =SUMIFS('Lista Movimenti'!$C:$C, 'Lista Movimenti'!$B:$B, $B17, 'Lista Movimenti'!$E:$E, "Spesa", 'Lista Movimenti'!$D:$D, ">=01/05/2026", 'Lista Movimenti'!$D:$D, "<=31/05/2026") -> 0 | H17: =SUMIFS('Lista Movimenti'!$C:$C, 'Lista Movimenti'!$B:$B, $B17, 'Lista Movimenti'!$E:$E, "Spesa", 'Lista Movimenti'!$D:$D, ">=01/06/2026", 'Lista Movimenti'!$D:$D, "<=30/06/2026") -> 35 | I17: =SUMIFS('Lista Movimenti'!$C:$C, 'Lista Movimenti'!$B:$B, $B17, 'Lista Movimenti'!$E:$E, "Spesa", 'Lista Movimenti'!$D:$D, ">=01/07/2026", 'Lista Movimenti'!$D:$D, "<=31/07/2026") -> 0 | J17: =SUMIFS('Lista Movimenti'!$C:$C, 'Lista Movimenti'!$B:$B, $B17, 'Lista Movimenti'!$E:$E, "Spesa", 'Lista Movimenti'!$D:$D, ">=01/08/2026", 'Lista Movimenti'!$D:$D, "<=31/08/2026") -> 0 | K17: =SUMIFS('Lista Movimenti'!$C:$C, 'Lista Movimenti'!$B:$B, $B17, 'Lista Movimenti'!$E:$E, "Spesa", 'Lista Movimenti'!$D:$D, ">=01/09/2026", 'Lista Movimenti'!$D:$D, "<=30/09/2026") -> 0 | L17: =SUMIFS('Lista Movimenti'!$C:$C, 'Lista Movimenti'!$B:$B, $B17, 'Lista Movimenti'!$E:$E, "Spesa", 'Lista Movimenti'!$D:$D, ">=01/10/2026", 'Lista Movimenti'!$D:$D, "<=31/10/2026") -> 0 | M17: =SUMIFS('Lista Movimenti'!$C:$C, 'Lista Movimenti'!$B:$B, $B17, 'Lista Movimenti'!$E:$E, "Spesa", 'Lista Movimenti'!$D:$D, ">=01/11/2026", 'Lista Movimenti'!$D:$D, "<=30/11/2026") -> 0 | N17: =SUMIFS('Lista Movimenti'!$C:$C, 'Lista Movimenti'!$B:$B, $B17, 'Lista Movimenti'!$E:$E, "Spesa", 'Lista Movimenti'!$D:$D, ">=01/12/2026", 'Lista Movimenti'!$D:$D, "<=31/12/2026") -> 25 | O17: =AVERAGE(C17:N17) -> 6 | P17: 15 | Q17: =SUM(C17:N17) -> 72
B18: 🚌 Trasporti | C18: =SUMIFS('Lista Movimenti'!C:C, 'Lista Movimenti'!B:B, B18, 'Lista Movimenti'!E:E, "Spesa", 'Lista Movimenti'!D:D, ">=01/01/2026", 'Lista Movimenti'!D:D, "<=31/01/2026") -> 60 | D18: =SUMIFS('Lista Movimenti'!$C:$C, 'Lista Movimenti'!$B:$B, $B18, 'Lista Movimenti'!$E:$E, "Spesa", 'Lista Movimenti'!$D:$D, ">=01/02/2026", 'Lista Movimenti'!$D:$D, "<=28/02/2026") -> 0 | E18: =SUMIFS('Lista Movimenti'!$C:$C, 'Lista Movimenti'!$B:$B, $B18, 'Lista Movimenti'!$E:$E, "Spesa", 'Lista Movimenti'!$D:$D, ">=01/03/2026", 'Lista Movimenti'!$D:$D, "<=31/03/2026") -> 0 | F18: =SUMIFS('Lista Movimenti'!$C:$C, 'Lista Movimenti'!$B:$B, $B18, 'Lista Movimenti'!$E:$E, "Spesa", 'Lista Movimenti'!$D:$D, ">=01/04/2026", 'Lista Movimenti'!$D:$D, "<=30/04/2026") -> 0 | G18: =SUMIFS('Lista Movimenti'!$C:$C, 'Lista Movimenti'!$B:$B, $B18, 'Lista Movimenti'!$E:$E, "Spesa", 'Lista Movimenti'!$D:$D, ">=01/05/2026", 'Lista Movimenti'!$D:$D, "<=31/05/2026") -> 0 | H18: =SUMIFS('Lista Movimenti'!$C:$C, 'Lista Movimenti'!$B:$B, $B18, 'Lista Movimenti'!$E:$E, "Spesa", 'Lista Movimenti'!$D:$D, ">=01/06/2026", 'Lista Movimenti'!$D:$D, "<=30/06/2026") -> 0 | I18: =SUMIFS('Lista Movimenti'!$C:$C, 'Lista Movimenti'!$B:$B, $B18, 'Lista Movimenti'!$E:$E, "Spesa", 'Lista Movimenti'!$D:$D, ">=01/07/2026", 'Lista Movimenti'!$D:$D, "<=31/07/2026") -> 0 | J18: =SUMIFS('Lista Movimenti'!$C:$C, 'Lista Movimenti'!$B:$B, $B18, 'Lista Movimenti'!$E:$E, "Spesa", 'Lista Movimenti'!$D:$D, ">=01/08/2026", 'Lista Movimenti'!$D:$D, "<=31/08/2026") -> 0 | K18: =SUMIFS('Lista Movimenti'!$C:$C, 'Lista Movimenti'!$B:$B, $B18, 'Lista Movimenti'!$E:$E, "Spesa", 'Lista Movimenti'!$D:$D, ">=01/09/2026", 'Lista Movimenti'!$D:$D, "<=30/09/2026") -> 0 | L18: =SUMIFS('Lista Movimenti'!$C:$C, 'Lista Movimenti'!$B:$B, $B18, 'Lista Movimenti'!$E:$E, "Spesa", 'Lista Movimenti'!$D:$D, ">=01/10/2026", 'Lista Movimenti'!$D:$D, "<=31/10/2026") -> 0 | M18: =SUMIFS('Lista Movimenti'!$C:$C, 'Lista Movimenti'!$B:$B, $B18, 'Lista Movimenti'!$E:$E, "Spesa", 'Lista Movimenti'!$D:$D, ">=01/11/2026", 'Lista Movimenti'!$D:$D, "<=30/11/2026") -> 0 | N18: =SUMIFS('Lista Movimenti'!$C:$C, 'Lista Movimenti'!$B:$B, $B18, 'Lista Movimenti'!$E:$E, "Spesa", 'Lista Movimenti'!$D:$D, ">=01/12/2026", 'Lista Movimenti'!$D:$D, "<=31/12/2026") -> 0 | O18: =AVERAGE(C18:N18) -> 5 | P18: 45 | Q18: =SUM(C18:N18) -> 60
B19: 👕 Vestiti | C19: =SUMIFS('Lista Movimenti'!C:C, 'Lista Movimenti'!B:B, B19, 'Lista Movimenti'!E:E, "Spesa", 'Lista Movimenti'!D:D, ">=01/01/2026", 'Lista Movimenti'!D:D, "<=31/01/2026") -> 112 | D19: =SUMIFS('Lista Movimenti'!$C:$C, 'Lista Movimenti'!$B:$B, $B19, 'Lista Movimenti'!$E:$E, "Spesa", 'Lista Movimenti'!$D:$D, ">=01/02/2026", 'Lista Movimenti'!$D:$D, "<=28/02/2026") -> 0 | E19: =SUMIFS('Lista Movimenti'!$C:$C, 'Lista Movimenti'!$B:$B, $B19, 'Lista Movimenti'!$E:$E, "Spesa", 'Lista Movimenti'!$D:$D, ">=01/03/2026", 'Lista Movimenti'!$D:$D, "<=31/03/2026") -> 0 | F19: =SUMIFS('Lista Movimenti'!$C:$C, 'Lista Movimenti'!$B:$B, $B19, 'Lista Movimenti'!$E:$E, "Spesa", 'Lista Movimenti'!$D:$D, ">=01/04/2026", 'Lista Movimenti'!$D:$D, "<=30/04/2026") -> 0 | G19: =SUMIFS('Lista Movimenti'!$C:$C, 'Lista Movimenti'!$B:$B, $B19, 'Lista Movimenti'!$E:$E, "Spesa", 'Lista Movimenti'!$D:$D, ">=01/05/2026", 'Lista Movimenti'!$D:$D, "<=31/05/2026") -> 0 | H19: =SUMIFS('Lista Movimenti'!$C:$C, 'Lista Movimenti'!$B:$B, $B19, 'Lista Movimenti'!$E:$E, "Spesa", 'Lista Movimenti'!$D:$D, ">=01/06/2026", 'Lista Movimenti'!$D:$D, "<=30/06/2026") -> 0 | I19: =SUMIFS('Lista Movimenti'!$C:$C, 'Lista Movimenti'!$B:$B, $B19, 'Lista Movimenti'!$E:$E, "Spesa", 'Lista Movimenti'!$D:$D, ">=01/07/2026", 'Lista Movimenti'!$D:$D, "<=31/07/2026") -> 0 | J19: =SUMIFS('Lista Movimenti'!$C:$C, 'Lista Movimenti'!$B:$B, $B19, 'Lista Movimenti'!$E:$E, "Spesa", 'Lista Movimenti'!$D:$D, ">=01/08/2026", 'Lista Movimenti'!$D:$D, "<=31/08/2026") -> 0 | K19: =SUMIFS('Lista Movimenti'!$C:$C, 'Lista Movimenti'!$B:$B, $B19, 'Lista Movimenti'!$E:$E, "Spesa", 'Lista Movimenti'!$D:$D, ">=01/09/2026", 'Lista Movimenti'!$D:$D, "<=30/09/2026") -> 0 | L19: =SUMIFS('Lista Movimenti'!$C:$C, 'Lista Movimenti'!$B:$B, $B19, 'Lista Movimenti'!$E:$E, "Spesa", 'Lista Movimenti'!$D:$D, ">=01/10/2026", 'Lista Movimenti'!$D:$D, "<=31/10/2026") -> 0 | M19: =SUMIFS('Lista Movimenti'!$C:$C, 'Lista Movimenti'!$B:$B, $B19, 'Lista Movimenti'!$E:$E, "Spesa", 'Lista Movimenti'!$D:$D, ">=01/11/2026", 'Lista Movimenti'!$D:$D, "<=30/11/2026") -> 0 | N19: =SUMIFS('Lista Movimenti'!$C:$C, 'Lista Movimenti'!$B:$B, $B19, 'Lista Movimenti'!$E:$E, "Spesa", 'Lista Movimenti'!$D:$D, ">=01/12/2026", 'Lista Movimenti'!$D:$D, "<=31/12/2026") -> 110 | O19: =AVERAGE(C19:N19) -> 18.5 | P19: 35 | Q19: =SUM(C19:N19) -> 222
A20: Totale Necessità | B20: -- Necessità -- | C20: =SUM(C13:C19) -> 668 | D20: =SUM(D13:D19) -> 780 | E20: =SUM(E13:E19) -> 0 | F20: =SUM(F13:F19) -> 300 | G20: =SUM(G13:G19) -> 0 | H20: =SUM(H13:H19) -> 35 | I20: =SUM(I13:I19) -> 599 | J20: =SUM(J13:J19) -> 55 | ... P20: =SUM(P13:P19) -> 665 | Q20: =SUM(C20:N20) -> 2917
A22: EXTRA | B22: -- Extra -- | C22: Gennaio | D22: Febbraio | E22: Marzo | F22: Aprile | G22: Maggio | H22: Giugno | I22: Luglio | J22: Agosto | K22: Settembre | L22: Ottobre | M22: Novembre | N22: Dicembre | O22: Media | P22: Obiettivo | Q22: Totale Annuo
B23: 🎫 Abbonamenti | C23: =SUMIFS('Lista Movimenti'!$C:$C, 'Lista Movimenti'!$B:$B, $B23, 'Lista Movimenti'!$E:$E, "Spesa", 'Lista Movimenti'!$D:$D, ">=01/01/2026", 'Lista Movimenti'!$D:$D, "<=31/01/2026") -> 9 | D23: =SUMIFS('Lista Movimenti'!$C:$C, 'Lista Movimenti'!$B:$B, $B23, 'Lista Movimenti'!$E:$E, "Spesa", 'Lista Movimenti'!$D:$D, ">=01/02/2026", 'Lista Movimenti'!$D:$D, "<=28/02/2026") -> 0 | E23: =SUMIFS('Lista Movimenti'!$C:$C, 'Lista Movimenti'!$B:$B, $B23, 'Lista Movimenti'!$E:$E, "Spesa", 'Lista Movimenti'!$D:$D, ">=01/03/2026", 'Lista Movimenti'!$D:$D, "<=31/03/2026") -> 0 | F23: =SUMIFS('Lista Movimenti'!$C:$C, 'Lista Movimenti'!$B:$B, $B23, 'Lista Movimenti'!$E:$E, "Spesa", 'Lista Movimenti'!$D:$D, ">=01/04/2026", 'Lista Movimenti'!$D:$D, "<=30/04/2026") -> 32 | G23: =SUMIFS('Lista Movimenti'!$C:$C, 'Lista Movimenti'!$B:$B, $B23, 'Lista Movimenti'!$E:$E, "Spesa", 'Lista Movimenti'!$D:$D, ">=01/05/2026", 'Lista Movimenti'!$D:$D, "<=31/05/2026") -> 0 | H23: =SUMIFS('Lista Movimenti'!$C:$C, 'Lista Movimenti'!$B:$B, $B23, 'Lista Movimenti'!$E:$E, "Spesa", 'Lista Movimenti'!$D:$D, ">=01/06/2026", 'Lista Movimenti'!$D:$D, "<=30/06/2026") -> 0 | I23: =SUMIFS('Lista Movimenti'!$C:$C, 'Lista Movimenti'!$B:$B, $B23, 'Lista Movimenti'!$E:$E, "Spesa", 'Lista Movimenti'!$D:$D, ">=01/07/2026", 'Lista Movimenti'!$D:$D, "<=31/07/2026") -> 12 | J23: =SUMIFS('Lista Movimenti'!$C:$C, 'Lista Movimenti'!$B:$B, $B23, 'Lista Movimenti'!$E:$E, "Spesa", 'Lista Movimenti'!$D:$D, ">=01/08/2026", 'Lista Movimenti'!$D:$D, "<=31/08/2026") -> 0 | K23: =SUMIFS('Lista Movimenti'!$C:$C, 'Lista Movimenti'!$B:$B, $B23, 'Lista Movimenti'!$E:$E, "Spesa", 'Lista Movimenti'!$D:$D, ">=01/09/2026", 'Lista Movimenti'!$D:$D, "<=30/09/2026") -> 0 | L23: =SUMIFS('Lista Movimenti'!$C:$C, 'Lista Movimenti'!$B:$B, $B23, 'Lista Movimenti'!$E:$E, "Spesa", 'Lista Movimenti'!$D:$D, ">=01/10/2026", 'Lista Movimenti'!$D:$D, "<=31/10/2026") -> 0 | M23: =SUMIFS('Lista Movimenti'!$C:$C, 'Lista Movimenti'!$B:$B, $B23, 'Lista Movimenti'!$E:$E, "Spesa", 'Lista Movimenti'!$D:$D, ">=01/11/2026", 'Lista Movimenti'!$D:$D, "<=30/11/2026") -> 12 | N23: =SUMIFS('Lista Movimenti'!$C:$C, 'Lista Movimenti'!$B:$B, $B23, 'Lista Movimenti'!$E:$E, "Spesa", 'Lista Movimenti'!$D:$D, ">=01/12/2026", 'Lista Movimenti'!$D:$D, "<=31/12/2026") -> 0 | O23: =AVERAGE(C23:N23) -> 5.4166667 | P23: 22 | Q23: =SUM(C23:N23) -> 65
B24: 🍔 Cibo fuori | C24: =SUMIFS('Lista Movimenti'!C:C, 'Lista Movimenti'!B:B, B24, 'Lista Movimenti'!E:E, "Spesa", 'Lista Movimenti'!D:D, ">=01/01/2026", 'Lista Movimenti'!D:D, "<=31/01/2026") -> 64 | D24: =SUMIFS('Lista Movimenti'!$C:$C, 'Lista Movimenti'!$B:$B, $B24, 'Lista Movimenti'!$E:$E, "Spesa", 'Lista Movimenti'!$D:$D, ">=01/02/2026", 'Lista Movimenti'!$D:$D, "<=28/02/2026") -> 79 | E24: =SUMIFS('Lista Movimenti'!$C:$C, 'Lista Movimenti'!$B:$B, $B24, 'Lista Movimenti'!$E:$E, "Spesa", 'Lista Movimenti'!$D:$D, ">=01/03/2026", 'Lista Movimenti'!$D:$D, "<=31/03/2026") -> 0 | F24: =SUMIFS('Lista Movimenti'!$C:$C, 'Lista Movimenti'!$B:$B, $B24, 'Lista Movimenti'!$E:$E, "Spesa", 'Lista Movimenti'!$D:$D, ">=01/04/2026", 'Lista Movimenti'!$D:$D, "<=30/04/2026") -> 0 | G24: =SUMIFS('Lista Movimenti'!$C:$C, 'Lista Movimenti'!$B:$B, $B24, 'Lista Movimenti'!$E:$E, "Spesa", 'Lista Movimenti'!$D:$D, ">=01/05/2026", 'Lista Movimenti'!$D:$D, "<=31/05/2026") -> 0 | H24: =SUMIFS('Lista Movimenti'!$C:$C, 'Lista Movimenti'!$B:$B, $B24, 'Lista Movimenti'!$E:$E, "Spesa", 'Lista Movimenti'!$D:$D, ">=01/06/2026", 'Lista Movimenti'!$D:$D, "<=30/06/2026") -> 0 | I24: =SUMIFS('Lista Movimenti'!$C:$C, 'Lista Movimenti'!$B:$B, $B24, 'Lista Movimenti'!$E:$E, "Spesa", 'Lista Movimenti'!$D:$D, ">=01/07/2026", 'Lista Movimenti'!$D:$D, "<=31/07/2026") -> 0 | J24: =SUMIFS('Lista Movimenti'!$C:$C, 'Lista Movimenti'!$B:$B, $B24, 'Lista Movimenti'!$E:$E, "Spesa", 'Lista Movimenti'!$D:$D, ">=01/08/2026", 'Lista Movimenti'!$D:$D, "<=31/08/2026") -> 0 | K24: =SUMIFS('Lista Movimenti'!$C:$C, 'Lista Movimenti'!$B:$B, $B24, 'Lista Movimenti'!$E:$E, "Spesa", 'Lista Movimenti'!$D:$D, ">=01/09/2026", 'Lista Movimenti'!$D:$D, "<=30/09/2026") -> 0 | L24: =SUMIFS('Lista Movimenti'!$C:$C, 'Lista Movimenti'!$B:$B, $B24, 'Lista Movimenti'!$E:$E, "Spesa", 'Lista Movimenti'!$D:$D, ">=01/10/2026", 'Lista Movimenti'!$D:$D, "<=31/10/2026") -> 0 | M24: =SUMIFS('Lista Movimenti'!$C:$C, 'Lista Movimenti'!$B:$B, $B24, 'Lista Movimenti'!$E:$E, "Spesa", 'Lista Movimenti'!$D:$D, ">=01/11/2026", 'Lista Movimenti'!$D:$D, "<=30/11/2026") -> 0 | N24: =SUMIFS('Lista Movimenti'!$C:$C, 'Lista Movimenti'!$B:$B, $B24, 'Lista Movimenti'!$E:$E, "Spesa", 'Lista Movimenti'!$D:$D, ">=01/12/2026", 'Lista Movimenti'!$D:$D, "<=31/12/2026") -> 120 | O24: =AVERAGE(C24:N24) -> 21.916667 | P24: 85 | Q24: =SUM(C24:N24) -> 263
B25: 🎬 Intrattenimento | C25: =SUMIFS('Lista Movimenti'!C:C, 'Lista Movimenti'!B:B, B25, 'Lista Movimenti'!E:E, "Spesa", 'Lista Movimenti'!D:D, ">=01/01/2026", 'Lista Movimenti'!D:D, "<=31/01/2026") -> 36 | D25: =SUMIFS('Lista Movimenti'!$C:$C, 'Lista Movimenti'!$B:$B, $B25, 'Lista Movimenti'!$E:$E, "Spesa", 'Lista Movimenti'!$D:$D, ">=01/02/2026", 'Lista Movimenti'!$D:$D, "<=28/02/2026") -> 0 | E25: =SUMIFS('Lista Movimenti'!$C:$C, 'Lista Movimenti'!$B:$B, $B25, 'Lista Movimenti'!$E:$E, "Spesa", 'Lista Movimenti'!$D:$D, ">=01/03/2026", 'Lista Movimenti'!$D:$D, "<=31/03/2026") -> 0 | F25: =SUMIFS('Lista Movimenti'!$C:$C, 'Lista Movimenti'!$B:$B, $B25, 'Lista Movimenti'!$E:$E, "Spesa", 'Lista Movimenti'!$D:$D, ">=01/04/2026", 'Lista Movimenti'!$D:$D, "<=30/04/2026") -> 0 | G25: =SUMIFS('Lista Movimenti'!$C:$C, 'Lista Movimenti'!$B:$B, $B25, 'Lista Movimenti'!$E:$E, "Spesa", 'Lista Movimenti'!$D:$D, ">=01/05/2026", 'Lista Movimenti'!$D:$D, "<=31/05/2026") -> 24 | H25: =SUMIFS('Lista Movimenti'!$C:$C, 'Lista Movimenti'!$B:$B, $B25, 'Lista Movimenti'!$E:$E, "Spesa", 'Lista Movimenti'!$D:$D, ">=01/06/2026", 'Lista Movimenti'!$D:$D, "<=30/06/2026") -> 22 | I25: =SUMIFS('Lista Movimenti'!$C:$C, 'Lista Movimenti'!$B:$B, $B25, 'Lista Movimenti'!$E:$E, "Spesa", 'Lista Movimenti'!$D:$D, ">=01/07/2026", 'Lista Movimenti'!$D:$D, "<=31/07/2026") -> 120 | J25: =SUMIFS('Lista Movimenti'!$C:$C, 'Lista Movimenti'!$B:$B, $B25, 'Lista Movimenti'!$E:$E, "Spesa", 'Lista Movimenti'!$D:$D, ">=01/08/2026", 'Lista Movimenti'!$D:$D, "<=31/08/2026") -> 0 | K25: =SUMIFS('Lista Movimenti'!$C:$C, 'Lista Movimenti'!$B:$B, $B25, 'Lista Movimenti'!$E:$E, "Spesa", 'Lista Movimenti'!$D:$D, ">=01/09/2026", 'Lista Movimenti'!$D:$D, "<=30/09/2026") -> 0 | L25: =SUMIFS('Lista Movimenti'!$C:$C, 'Lista Movimenti'!$B:$B, $B25, 'Lista Movimenti'!$E:$E, "Spesa", 'Lista Movimenti'!$D:$D, ">=01/10/2026", 'Lista Movimenti'!$D:$D, "<=31/10/2026") -> 0 | M25: =SUMIFS('Lista Movimenti'!$C:$C, 'Lista Movimenti'!$B:$B, $B25, 'Lista Movimenti'!$E:$E, "Spesa", 'Lista Movimenti'!$D:$D, ">=01/11/2026", 'Lista Movimenti'!$D:$D, "<=30/11/2026") -> 0 | N25: =SUMIFS('Lista Movimenti'!$C:$C, 'Lista Movimenti'!$B:$B, $B25, 'Lista Movimenti'!$E:$E, "Spesa", 'Lista Movimenti'!$D:$D, ">=01/12/2026", 'Lista Movimenti'!$D:$D, "<=31/12/2026") -> 0 | O25: =AVERAGE(C25:N25) -> 16.833333 | P25: 24 | Q25: =SUM(C25:N25) -> 202
B26: 🎁 Regali | C26: =SUMIFS('Lista Movimenti'!C:C, 'Lista Movimenti'!B:B, B26, 'Lista Movimenti'!E:E, "Spesa", 'Lista Movimenti'!D:D, ">=01/01/2026", 'Lista Movimenti'!D:D, "<=31/01/2026") -> 200 | D26: =SUMIFS('Lista Movimenti'!$C:$C, 'Lista Movimenti'!$B:$B, $B26, 'Lista Movimenti'!$E:$E, "Spesa", 'Lista Movimenti'!$D:$D, ">=01/02/2026", 'Lista Movimenti'!$D:$D, "<=28/02/2026") -> 0 | E26: =SUMIFS('Lista Movimenti'!$C:$C, 'Lista Movimenti'!$B:$B, $B26, 'Lista Movimenti'!$E:$E, "Spesa", 'Lista Movimenti'!$D:$D, ">=01/03/2026", 'Lista Movimenti'!$D:$D, "<=31/03/2026") -> 0 | F26: =SUMIFS('Lista Movimenti'!$C:$C, 'Lista Movimenti'!$B:$B, $B26, 'Lista Movimenti'!$E:$E, "Spesa", 'Lista Movimenti'!$D:$D, ">=01/04/2026", 'Lista Movimenti'!$D:$D, "<=30/04/2026") -> 0 | G26: =SUMIFS('Lista Movimenti'!$C:$C, 'Lista Movimenti'!$B:$B, $B26, 'Lista Movimenti'!$E:$E, "Spesa", 'Lista Movimenti'!$D:$D, ">=01/05/2026", 'Lista Movimenti'!$D:$D, "<=31/05/2026") -> 50 | H26: =SUMIFS('Lista Movimenti'!$C:$C, 'Lista Movimenti'!$B:$B, $B26, 'Lista Movimenti'!$E:$E, "Spesa", 'Lista Movimenti'!$D:$D, ">=01/06/2026", 'Lista Movimenti'!$D:$D, "<=30/06/2026") -> 0 | I26: =SUMIFS('Lista Movimenti'!$C:$C, 'Lista Movimenti'!$B:$B, $B26, 'Lista Movimenti'!$E:$E, "Spesa", 'Lista Movimenti'!$D:$D, ">=01/07/2026", 'Lista Movimenti'!$D:$D, "<=31/07/2026") -> 0 | J26: =SUMIFS('Lista Movimenti'!$C:$C, 'Lista Movimenti'!$B:$B, $B26, 'Lista Movimenti'!$E:$E, "Spesa", 'Lista Movimenti'!$D:$D, ">=01/08/2026", 'Lista Movimenti'!$D:$D, "<=31/08/2026") -> 0 | K26: =SUMIFS('Lista Movimenti'!$C:$C, 'Lista Movimenti'!$B:$B, $B26, 'Lista Movimenti'!$E:$E, "Spesa", 'Lista Movimenti'!$D:$D, ">=01/09/2026", 'Lista Movimenti'!$D:$D, "<=30/09/2026") -> 0 | L26: =SUMIFS('Lista Movimenti'!$C:$C, 'Lista Movimenti'!$B:$B, $B26, 'Lista Movimenti'!$E:$E, "Spesa", 'Lista Movimenti'!$D:$D, ">=01/10/2026", 'Lista Movimenti'!$D:$D, "<=31/10/2026") -> 0 | M26: =SUMIFS('Lista Movimenti'!$C:$C, 'Lista Movimenti'!$B:$B, $B26, 'Lista Movimenti'!$E:$E, "Spesa", 'Lista Movimenti'!$D:$D, ">=01/11/2026", 'Lista Movimenti'!$D:$D, "<=30/11/2026") -> 0 | N26: =SUMIFS('Lista Movimenti'!$C:$C, 'Lista Movimenti'!$B:$B, $B26, 'Lista Movimenti'!$E:$E, "Spesa", 'Lista Movimenti'!$D:$D, ">=01/12/2026", 'Lista Movimenti'!$D:$D, "<=31/12/2026") -> 0 | O26: =AVERAGE(C26:N26) -> 20.833333 | P26: 20 | Q26: =SUM(C26:N26) -> 250
B27: ✈️ Viaggi/Vacanze | C27: =SUMIFS('Lista Movimenti'!C:C, 'Lista Movimenti'!B:B, B27, 'Lista Movimenti'!E:E, "Spesa", 'Lista Movimenti'!D:D, ">=01/01/2026", 'Lista Movimenti'!D:D, "<=31/01/2026") -> 0 | D27: =SUMIFS('Lista Movimenti'!$C:$C, 'Lista Movimenti'!$B:$B, $B27, 'Lista Movimenti'!$E:$E, "Spesa", 'Lista Movimenti'!$D:$D, ">=01/02/2026", 'Lista Movimenti'!$D:$D, "<=28/02/2026") -> 0 | E27: =SUMIFS('Lista Movimenti'!$C:$C, 'Lista Movimenti'!$B:$B, $B27, 'Lista Movimenti'!$E:$E, "Spesa", 'Lista Movimenti'!$D:$D, ">=01/03/2026", 'Lista Movimenti'!$D:$D, "<=31/03/2026") -> 350 | F27: =SUMIFS('Lista Movimenti'!$C:$C, 'Lista Movimenti'!$B:$B, $B27, 'Lista Movimenti'!$E:$E, "Spesa", 'Lista Movimenti'!$D:$D, ">=01/04/2026", 'Lista Movimenti'!$D:$D, "<=30/04/2026") -> 0 | G27: =SUMIFS('Lista Movimenti'!$C:$C, 'Lista Movimenti'!$B:$B, $B27, 'Lista Movimenti'!$E:$E, "Spesa", 'Lista Movimenti'!$D:$D, ">=01/05/2026", 'Lista Movimenti'!$D:$D, "<=31/05/2026") -> 300 | H27: =SUMIFS('Lista Movimenti'!$C:$C, 'Lista Movimenti'!$B:$B, $B27, 'Lista Movimenti'!$E:$E, "Spesa", 'Lista Movimenti'!$D:$D, ">=01/06/2026", 'Lista Movimenti'!$D:$D, "<=30/06/2026") -> 0 | I27: =SUMIFS('Lista Movimenti'!$C:$C, 'Lista Movimenti'!$B:$B, $B27, 'Lista Movimenti'!$E:$E, "Spesa", 'Lista Movimenti'!$D:$D, ">=01/07/2026", 'Lista Movimenti'!$D:$D, "<=31/07/2026") -> 120 | J27: =SUMIFS('Lista Movimenti'!$C:$C, 'Lista Movimenti'!$B:$B, $B27, 'Lista Movimenti'!$E:$E, "Spesa", 'Lista Movimenti'!$D:$D, ">=01/08/2026", 'Lista Movimenti'!$D:$D, "<=31/08/2026") -> 0 | K27: =SUMIFS('Lista Movimenti'!$C:$C, 'Lista Movimenti'!$B:$B, $B27, 'Lista Movimenti'!$E:$E, "Spesa", 'Lista Movimenti'!$D:$D, ">=01/09/2026", 'Lista Movimenti'!$D:$D, "<=30/09/2026") -> 150 | L27: =SUMIFS('Lista Movimenti'!$C:$C, 'Lista Movimenti'!$B:$B, $B27, 'Lista Movimenti'!$E:$E, "Spesa", 'Lista Movimenti'!$D:$D, ">=01/10/2026", 'Lista Movimenti'!$D:$D, "<=31/10/2026") -> 0 | M27: =SUMIFS('Lista Movimenti'!$C:$C, 'Lista Movimenti'!$B:$B, $B27, 'Lista Movimenti'!$E:$E, "Spesa", 'Lista Movimenti'!$D:$D, ">=01/11/2026", 'Lista Movimenti'!$D:$D, "<=30/11/2026") -> 0 | N27: =SUMIFS('Lista Movimenti'!$C:$C, 'Lista Movimenti'!$B:$B, $B27, 'Lista Movimenti'!$E:$E, "Spesa", 'Lista Movimenti'!$D:$D, ">=01/12/2026", 'Lista Movimenti'!$D:$D, "<=31/12/2026") -> 0 | O27: =AVERAGE(C27:N27) -> 76.666667 | P27: 60 | Q27: =SUM(C27:N27) -> 920
B28: 📚 Cultura | C28: =SUMIFS('Lista Movimenti'!C:C, 'Lista Movimenti'!B:B, B28, 'Lista Movimenti'!E:E, "Spesa", 'Lista Movimenti'!D:D, ">=01/01/2026", 'Lista Movimenti'!D:D, "<=31/01/2026") -> 32 | D28: =SUMIFS('Lista Movimenti'!$C:$C, 'Lista Movimenti'!$B:$B, $B28, 'Lista Movimenti'!$E:$E, "Spesa", 'Lista Movimenti'!$D:$D, ">=01/02/2026", 'Lista Movimenti'!$D:$D, "<=28/02/2026") -> 0 | E28: =SUMIFS('Lista Movimenti'!$C:$C, 'Lista Movimenti'!$B:$B, $B28, 'Lista Movimenti'!$E:$E, "Spesa", 'Lista Movimenti'!$D:$D, ">=01/03/2026", 'Lista Movimenti'!$D:$D, "<=31/03/2026") -> 0 | F28: =SUMIFS('Lista Movimenti'!$C:$C, 'Lista Movimenti'!$B:$B, $B28, 'Lista Movimenti'!$E:$E, "Spesa", 'Lista Movimenti'!$D:$D, ">=01/04/2026", 'Lista Movimenti'!$D:$D, "<=30/04/2026") -> 0 | G28: =SUMIFS('Lista Movimenti'!$C:$C, 'Lista Movimenti'!$B:$B, $B28, 'Lista Movimenti'!$E:$E, "Spesa", 'Lista Movimenti'!$D:$D, ">=01/05/2026", 'Lista Movimenti'!$D:$D, "<=31/05/2026") -> 0 | H28: =SUMIFS('Lista Movimenti'!$C:$C, 'Lista Movimenti'!$B:$B, $B28, 'Lista Movimenti'!$E:$E, "Spesa", 'Lista Movimenti'!$D:$D, ">=01/06/2026", 'Lista Movimenti'!$D:$D, "<=30/06/2026") -> 0 | I28: =SUMIFS('Lista Movimenti'!$C:$C, 'Lista Movimenti'!$B:$B, $B28, 'Lista Movimenti'!$E:$E, "Spesa", 'Lista Movimenti'!$D:$D, ">=01/07/2026", 'Lista Movimenti'!$D:$D, "<=31/07/2026") -> 0 | J28: =SUMIFS('Lista Movimenti'!$C:$C, 'Lista Movimenti'!$B:$B, $B28, 'Lista Movimenti'!$E:$E, "Spesa", 'Lista Movimenti'!$D:$D, ">=01/08/2026", 'Lista Movimenti'!$D:$D, "<=31/08/2026") -> 10 | K28: =SUMIFS('Lista Movimenti'!$C:$C, 'Lista Movimenti'!$B:$B, $B28, 'Lista Movimenti'!$E:$E, "Spesa", 'Lista Movimenti'!$D:$D, ">=01/09/2026", 'Lista Movimenti'!$D:$D, "<=30/09/2026") -> 0 | L28: =SUMIFS('Lista Movimenti'!$C:$C, 'Lista Movimenti'!$B:$B, $B28, 'Lista Movimenti'!$E:$E, "Spesa", 'Lista Movimenti'!$D:$D, ">=01/10/2026", 'Lista Movimenti'!$D:$D, "<=31/10/2026") -> 10 | M28: =SUMIFS('Lista Movimenti'!$C:$C, 'Lista Movimenti'!$B:$B, $B28, 'Lista Movimenti'!$E:$E, "Spesa", 'Lista Movimenti'!$D:$D, ">=01/11/2026", 'Lista Movimenti'!$D:$D, "<=30/11/2026") -> 0 | N28: =SUMIFS('Lista Movimenti'!$C:$C, 'Lista Movimenti'!$B:$B, $B28, 'Lista Movimenti'!$E:$E, "Spesa", 'Lista Movimenti'!$D:$D, ">=01/12/2026", 'Lista Movimenti'!$D:$D, "<=31/12/2026") -> 0 | O28: =AVERAGE(C28:N28) -> 4.3333333 | P28: 40 | Q28: =SUM(C28:N28) -> 52
B29: 💅 Cura personale | C29: =SUMIFS('Lista Movimenti'!C:C, 'Lista Movimenti'!B:B, B29, 'Lista Movimenti'!E:E, "Spesa", 'Lista Movimenti'!D:D, ">=01/01/2026", 'Lista Movimenti'!D:D, "<=31/01/2026") -> 100 | D29: =SUMIFS('Lista Movimenti'!$C:$C, 'Lista Movimenti'!$B:$B, $B29, 'Lista Movimenti'!$E:$E, "Spesa", 'Lista Movimenti'!$D:$D, ">=01/02/2026", 'Lista Movimenti'!$D:$D, "<=28/02/2026") -> 0 | E29: =SUMIFS('Lista Movimenti'!$C:$C, 'Lista Movimenti'!$B:$B, $B29, 'Lista Movimenti'!$E:$E, "Spesa", 'Lista Movimenti'!$D:$D, ">=01/03/2026", 'Lista Movimenti'!$D:$D, "<=31/03/2026") -> 30 | F29: =SUMIFS('Lista Movimenti'!$C:$C, 'Lista Movimenti'!$B:$B, $B29, 'Lista Movimenti'!$E:$E, "Spesa", 'Lista Movimenti'!$D:$D, ">=01/04/2026", 'Lista Movimenti'!$D:$D, "<=30/04/2026") -> 0 | G29: =SUMIFS('Lista Movimenti'!$C:$C, 'Lista Movimenti'!$B:$B, $B29, 'Lista Movimenti'!$E:$E, "Spesa", 'Lista Movimenti'!$D:$D, ">=01/05/2026", 'Lista Movimenti'!$D:$D, "<=31/05/2026") -> 0 | H29: =SUMIFS('Lista Movimenti'!$C:$C, 'Lista Movimenti'!$B:$B, $B29, 'Lista Movimenti'!$E:$E, "Spesa", 'Lista Movimenti'!$D:$D, ">=01/06/2026", 'Lista Movimenti'!$D:$D, "<=30/06/2026") -> 0 | I29: =SUMIFS('Lista Movimenti'!$C:$C, 'Lista Movimenti'!$B:$B, $B29, 'Lista Movimenti'!$E:$E, "Spesa", 'Lista Movimenti'!$D:$D, ">=01/07/2026", 'Lista Movimenti'!$D:$D, "<=31/07/2026") -> 20 | J29: =SUMIFS('Lista Movimenti'!$C:$C, 'Lista Movimenti'!$B:$B, $B29, 'Lista Movimenti'!$E:$E, "Spesa", 'Lista Movimenti'!$D:$D, ">=01/08/2026", 'Lista Movimenti'!$D:$D, "<=31/08/2026") -> 0 | K29: =SUMIFS('Lista Movimenti'!$C:$C, 'Lista Movimenti'!$B:$B, $B29, 'Lista Movimenti'!$E:$E, "Spesa", 'Lista Movimenti'!$D:$D, ">=01/09/2026", 'Lista Movimenti'!$D:$D, "<=30/09/2026") -> 0 | L29: =SUMIFS('Lista Movimenti'!$C:$C, 'Lista Movimenti'!$B:$B, $B29, 'Lista Movimenti'!$E:$E, "Spesa", 'Lista Movimenti'!$D:$D, ">=01/10/2026", 'Lista Movimenti'!$D:$D, "<=31/10/2026") -> 0 | M29: =SUMIFS('Lista Movimenti'!$C:$C, 'Lista Movimenti'!$B:$B, $B29, 'Lista Movimenti'!$E:$E, "Spesa", 'Lista Movimenti'!$D:$D, ">=01/11/2026", 'Lista Movimenti'!$D:$D, "<=30/11/2026") -> 0 | N29: =SUMIFS('Lista Movimenti'!$C:$C, 'Lista Movimenti'!$B:$B, $B29, 'Lista Movimenti'!$E:$E, "Spesa", 'Lista Movimenti'!$D:$D, ">=01/12/2026", 'Lista Movimenti'!$D:$D, "<=31/12/2026") -> 0 | O29: =AVERAGE(C29:N29) -> 12.5 | P29: 95 | Q29: =SUM(C29:N29) -> 150
B30: 🌟 Altro extra | C30: =SUMIFS('Lista Movimenti'!C:C, 'Lista Movimenti'!B:B, B30, 'Lista Movimenti'!E:E, "Spesa", 'Lista Movimenti'!D:D, ">=01/01/2026", 'Lista Movimenti'!D:D, "<=31/01/2026") -> 0 | D30: =SUMIFS('Lista Movimenti'!$C:$C, 'Lista Movimenti'!$B:$B, $B30, 'Lista Movimenti'!$E:$E, "Spesa", 'Lista Movimenti'!$D:$D, ">=01/02/2026", 'Lista Movimenti'!$D:$D, "<=28/02/2026") -> 112 | E30: =SUMIFS('Lista Movimenti'!$C:$C, 'Lista Movimenti'!$B:$B, $B30, 'Lista Movimenti'!$E:$E, "Spesa", 'Lista Movimenti'!$D:$D, ">=01/03/2026", 'Lista Movimenti'!$D:$D, "<=31/03/2026") -> 0 | F30: =SUMIFS('Lista Movimenti'!$C:$C, 'Lista Movimenti'!$B:$B, $B30, 'Lista Movimenti'!$E:$E, "Spesa", 'Lista Movimenti'!$D:$D, ">=01/04/2026", 'Lista Movimenti'!$D:$D, "<=30/04/2026") -> 0 | G30: =SUMIFS('Lista Movimenti'!$C:$C, 'Lista Movimenti'!$B:$B, $B30, 'Lista Movimenti'!$E:$E, "Spesa", 'Lista Movimenti'!$D:$D, ">=01/05/2026", 'Lista Movimenti'!$D:$D, "<=31/05/2026") -> 0 | H30: =SUMIFS('Lista Movimenti'!$C:$C, 'Lista Movimenti'!$B:$B, $B30, 'Lista Movimenti'!$E:$E, "Spesa", 'Lista Movimenti'!$D:$D, ">=01/06/2026", 'Lista Movimenti'!$D:$D, "<=30/06/2026") -> 0 | I30: =SUMIFS('Lista Movimenti'!$C:$C, 'Lista Movimenti'!$B:$B, $B30, 'Lista Movimenti'!$E:$E, "Spesa", 'Lista Movimenti'!$D:$D, ">=01/07/2026", 'Lista Movimenti'!$D:$D, "<=31/07/2026") -> 30 | J30: =SUMIFS('Lista Movimenti'!$C:$C, 'Lista Movimenti'!$B:$B, $B30, 'Lista Movimenti'!$E:$E, "Spesa", 'Lista Movimenti'!$D:$D, ">=01/08/2026", 'Lista Movimenti'!$D:$D, "<=31/08/2026") -> 0 | K30: =SUMIFS('Lista Movimenti'!$C:$C, 'Lista Movimenti'!$B:$B, $B30, 'Lista Movimenti'!$E:$E, "Spesa", 'Lista Movimenti'!$D:$D, ">=01/09/2026", 'Lista Movimenti'!$D:$D, "<=30/09/2026") -> 0 | L30: =SUMIFS('Lista Movimenti'!$C:$C, 'Lista Movimenti'!$B:$B, $B30, 'Lista Movimenti'!$E:$E, "Spesa", 'Lista Movimenti'!$D:$D, ">=01/10/2026", 'Lista Movimenti'!$D:$D, "<=31/10/2026") -> 0 | M30: =SUMIFS('Lista Movimenti'!$C:$C, 'Lista Movimenti'!$B:$B, $B30, 'Lista Movimenti'!$E:$E, "Spesa", 'Lista Movimenti'!$D:$D, ">=01/11/2026", 'Lista Movimenti'!$D:$D, "<=30/11/2026") -> 0 | N30: =SUMIFS('Lista Movimenti'!$C:$C, 'Lista Movimenti'!$B:$B, $B30, 'Lista Movimenti'!$E:$E, "Spesa", 'Lista Movimenti'!$D:$D, ">=01/12/2026", 'Lista Movimenti'!$D:$D, "<=31/12/2026") -> 0 | O30: =AVERAGE(C30:N30) -> 11.833333 | P30: 13 | Q30: =SUM(C30:N30) -> 142
A31: Totale Extra | B31: -- Extra -- | C31: =SUM(C23:C30) -> 441 | D31: =SUM(D23:D30) -> 191 | E31: =SUM(E23:E30) -> 380 | F31: =SUM(F23:F30) -> 32 | G31: =SUM(G23:G30) -> 374 | H31: =SUM(H23:H30) -> 22 | I31: =SUM(I23:I30) -> 302 | J31: =SUM(J23:J30) -> 10 | ... P31: =SUM(P23:P30) -> 359 | Q31: =SUM(C31:N31) -> 2044
A33: Totale Uscite | C33: =(C31 + C20) -> 1109 | D33: =(D31 + D20) -> 971 | E33: =(E31 + E20) -> 380 | F33: =(F31 + F20) -> 332 | G33: =(G31 + G20) -> 374 | H33: =(H31 + H20) -> 57 | I33: =(I31 + I20) -> 901 | J33: =(J31 + J20) -> 65 | ... Q33: =(Q31 + Q20) -> 4961
A34: Differenza Entrate Uscite | C34: =(B8-C33) -> 441 | D34: =(C8-D33) -> 429 | E34: =(D8-E33) -> 1130 | F34: =(E8-F33) -> 968 | G34: =(F8-G33) -> 886 | H34: =(G8-H33) -> 1393 | I34: =(H8-I33) -> 99 | J34: =(I8-J33) -> 1245 | ... O34: =(N8-O33) -> 961.58333 | Q34: =(P8-Q33) -> 11539
A37: Categoria | B37: Gennaio | C37: Febbraio | D37: Marzo | E37: Aprile | F37: Maggio | G37: Giugno | H37: Luglio | I37: Agosto | J37: Settembre | K37: Ottobre | L37: Novembre | M37: Dicembre | N37: Media | O37: Obiettivo
A38: 🏠 Casa | B38: =SUMIFS('Lista Movimenti'!$C:$C, 'Lista Movimenti'!$B:$B, $A38, 'Lista Movimenti'!$E:$E, "Risparmio", 'Lista Movimenti'!$D:$D, ">=01/01/2026", 'Lista Movimenti'!$D:$D, "<=31/01/2026") -> 0 | C38: =SUMIFS('Lista Movimenti'!$C:$C, 'Lista Movimenti'!$B:$B, $A38, 'Lista Movimenti'!$E:$E, "Risparmio", 'Lista Movimenti'!$D:$D, ">=01/02/2026", 'Lista Movimenti'!$D:$D, "<=28/02/2026") -> 0 | D38: =SUMIFS('Lista Movimenti'!$C:$C, 'Lista Movimenti'!$B:$B, $A38, 'Lista Movimenti'!$E:$E, "Risparmio", 'Lista Movimenti'!$D:$D, ">=01/03/2026", 'Lista Movimenti'!$D:$D, "<=31/03/2026") -> 0 | E38: =SUMIFS('Lista Movimenti'!$C:$C, 'Lista Movimenti'!$B:$B, $A38, 'Lista Movimenti'!$E:$E, "Risparmio", 'Lista Movimenti'!$D:$D, ">=01/04/2026", 'Lista Movimenti'!$D:$D, "<=30/04/2026") -> 300 | F38: =SUMIFS('Lista Movimenti'!$C:$C, 'Lista Movimenti'!$B:$B, $A38, 'Lista Movimenti'!$E:$E, "Risparmio", 'Lista Movimenti'!$D:$D, ">=01/05/2026", 'Lista Movimenti'!$D:$D, "<=31/05/2026") -> 500 | G38: =SUMIFS('Lista Movimenti'!$C:$C, 'Lista Movimenti'!$B:$B, $A38, 'Lista Movimenti'!$E:$E, "Risparmio", 'Lista Movimenti'!$D:$D, ">=01/06/2026", 'Lista Movimenti'!$D:$D, "<=30/06/2026") -> 0 | H38: =SUMIFS('Lista Movimenti'!$C:$C, 'Lista Movimenti'!$B:$B, $A38, 'Lista Movimenti'!$E:$E, "Risparmio", 'Lista Movimenti'!$D:$D, ">=01/07/2026", 'Lista Movimenti'!$D:$D, "<=31/07/2026") -> 0 | I38: =SUMIFS('Lista Movimenti'!$C:$C, 'Lista Movimenti'!$B:$B, $A38, 'Lista Movimenti'!$E:$E, "Risparmio", 'Lista Movimenti'!$D:$D, ">=01/08/2026", 'Lista Movimenti'!$D:$D, "<=31/08/2026") -> 0 | J38: =SUMIFS('Lista Movimenti'!$C:$C, 'Lista Movimenti'!$B:$B, $A38, 'Lista Movimenti'!$E:$E, "Risparmio", 'Lista Movimenti'!$D:$D, ">=01/09/2026", 'Lista Movimenti'!$D:$D, "<=30/09/2026") -> 230 | K38: =SUMIFS('Lista Movimenti'!$C:$C, 'Lista Movimenti'!$B:$B, $A38, 'Lista Movimenti'!$E:$E, "Risparmio", 'Lista Movimenti'!$D:$D, ">=01/10/2026", 'Lista Movimenti'!$D:$D, "<=31/10/2026") -> 115 | L38: =SUMIFS('Lista Movimenti'!$C:$C, 'Lista Movimenti'!$B:$B, $A38, 'Lista Movimenti'!$E:$E, "Risparmio", 'Lista Movimenti'!$D:$D, ">=01/11/2026", 'Lista Movimenti'!$D:$D, "<=30/11/2026") -> 0 | M38: =SUMIFS('Lista Movimenti'!$C:$C, 'Lista Movimenti'!$B:$B, $A38, 'Lista Movimenti'!$E:$E, "Risparmio", 'Lista Movimenti'!$D:$D, ">=01/12/2026", 'Lista Movimenti'!$D:$D, "<=31/12/2026") -> 250 | N38: =AVERAGE(B38:M38) -> 116.25
A39: 🍲 Cibo/Spesa | B39: =SUMIFS('Lista Movimenti'!C:C, 'Lista Movimenti'!B:B, A39, 'Lista Movimenti'!E:E, "Risparmio", 'Lista Movimenti'!D:D, ">=01/01/2026", 'Lista Movimenti'!D:D, "<=31/01/2026") -> 0 | C39: =SUMIFS('Lista Movimenti'!$C:$C, 'Lista Movimenti'!$B:$B, $A39, 'Lista Movimenti'!$E:$E, "Risparmio", 'Lista Movimenti'!$D:$D, ">=01/02/2026", 'Lista Movimenti'!$D:$D, "<=28/02/2026") -> 0 | D39: =SUMIFS('Lista Movimenti'!$C:$C, 'Lista Movimenti'!$B:$B, $A39, 'Lista Movimenti'!$E:$E, "Risparmio", 'Lista Movimenti'!$D:$D, ">=01/03/2026", 'Lista Movimenti'!$D:$D, "<=31/03/2026") -> 0 | E39: =SUMIFS('Lista Movimenti'!$C:$C, 'Lista Movimenti'!$B:$B, $A39, 'Lista Movimenti'!$E:$E, "Risparmio", 'Lista Movimenti'!$D:$D, ">=01/04/2026", 'Lista Movimenti'!$D:$D, "<=30/04/2026") -> 0 | F39: =SUMIFS('Lista Movimenti'!$C:$C, 'Lista Movimenti'!$B:$B, $A39, 'Lista Movimenti'!$E:$E, "Risparmio", 'Lista Movimenti'!$D:$D, ">=01/05/2026", 'Lista Movimenti'!$D:$D, "<=31/05/2026") -> 0 | G39: =SUMIFS('Lista Movimenti'!$C:$C, 'Lista Movimenti'!$B:$B, $A39, 'Lista Movimenti'!$E:$E, "Risparmio", 'Lista Movimenti'!$D:$D, ">=01/06/2026", 'Lista Movimenti'!$D:$D, "<=30/06/2026") -> 0 | H39: =SUMIFS('Lista Movimenti'!$C:$C, 'Lista Movimenti'!$B:$B, $A39, 'Lista Movimenti'!$E:$E, "Risparmio", 'Lista Movimenti'!$D:$D, ">=01/07/2026", 'Lista Movimenti'!$D:$D, "<=31/07/2026") -> 0 | I39: =SUMIFS('Lista Movimenti'!$C:$C, 'Lista Movimenti'!$B:$B, $A39, 'Lista Movimenti'!$E:$E, "Risparmio", 'Lista Movimenti'!$D:$D, ">=01/08/2026", 'Lista Movimenti'!$D:$D, "<=31/08/2026") -> 0 | J39: =SUMIFS('Lista Movimenti'!$C:$C, 'Lista Movimenti'!$B:$B, $A39, 'Lista Movimenti'!$E:$E, "Risparmio", 'Lista Movimenti'!$D:$D, ">=01/09/2026", 'Lista Movimenti'!$D:$D, "<=30/09/2026") -> 0 | K39: =SUMIFS('Lista Movimenti'!$C:$C, 'Lista Movimenti'!$B:$B, $A39, 'Lista Movimenti'!$E:$E, "Risparmio", 'Lista Movimenti'!$D:$D, ">=01/10/2026", 'Lista Movimenti'!$D:$D, "<=31/10/2026") -> 0 | L39: =SUMIFS('Lista Movimenti'!$C:$C, 'Lista Movimenti'!$B:$B, $A39, 'Lista Movimenti'!$E:$E, "Risparmio", 'Lista Movimenti'!$D:$D, ">=01/11/2026", 'Lista Movimenti'!$D:$D, "<=30/11/2026") -> 0 | M39: =SUMIFS('Lista Movimenti'!$C:$C, 'Lista Movimenti'!$B:$B, $A39, 'Lista Movimenti'!$E:$E, "Risparmio", 'Lista Movimenti'!$D:$D, ">=01/12/2026", 'Lista Movimenti'!$D:$D, "<=31/12/2026") -> 0 | N39: =AVERAGE(B39:M39) -> 0
A40: 🚑 Sanità | B40: =SUMIFS('Lista Movimenti'!C:C, 'Lista Movimenti'!B:B, A40, 'Lista Movimenti'!E:E, "Risparmio", 'Lista Movimenti'!D:D, ">=01/01/2026", 'Lista Movimenti'!D:D, "<=31/01/2026") -> 0 | C40: =SUMIFS('Lista Movimenti'!$C:$C, 'Lista Movimenti'!$B:$B, $A40, 'Lista Movimenti'!$E:$E, "Risparmio", 'Lista Movimenti'!$D:$D, ">=01/02/2026", 'Lista Movimenti'!$D:$D, "<=28/02/2026") -> 0 | D40: =SUMIFS('Lista Movimenti'!$C:$C, 'Lista Movimenti'!$B:$B, $A40, 'Lista Movimenti'!$E:$E, "Risparmio", 'Lista Movimenti'!$D:$D, ">=01/03/2026", 'Lista Movimenti'!$D:$D, "<=31/03/2026") -> 0 | E40: =SUMIFS('Lista Movimenti'!$C:$C, 'Lista Movimenti'!$B:$B, $A40, 'Lista Movimenti'!$E:$E, "Risparmio", 'Lista Movimenti'!$D:$D, ">=01/04/2026", 'Lista Movimenti'!$D:$D, "<=30/04/2026") -> 0 | F40: =SUMIFS('Lista Movimenti'!$C:$C, 'Lista Movimenti'!$B:$B, $A40, 'Lista Movimenti'!$E:$E, "Risparmio", 'Lista Movimenti'!$D:$D, ">=01/05/2026", 'Lista Movimenti'!$D:$D, "<=31/05/2026") -> 0 | G40: =SUMIFS('Lista Movimenti'!$C:$C, 'Lista Movimenti'!$B:$B, $A40, 'Lista Movimenti'!$E:$E, "Risparmio", 'Lista Movimenti'!$D:$D, ">=01/06/2026", 'Lista Movimenti'!$D:$D, "<=30/06/2026") -> 0 | H40: =SUMIFS('Lista Movimenti'!$C:$C, 'Lista Movimenti'!$B:$B, $A40, 'Lista Movimenti'!$E:$E, "Risparmio", 'Lista Movimenti'!$D:$D, ">=01/07/2026", 'Lista Movimenti'!$D:$D, "<=31/07/2026") -> 0 | I40: =SUMIFS('Lista Movimenti'!$C:$C, 'Lista Movimenti'!$B:$B, $A40, 'Lista Movimenti'!$E:$E, "Risparmio", 'Lista Movimenti'!$D:$D, ">=01/08/2026", 'Lista Movimenti'!$D:$D, "<=31/08/2026") -> 0 | J40: =SUMIFS('Lista Movimenti'!$C:$C, 'Lista Movimenti'!$B:$B, $A40, 'Lista Movimenti'!$E:$E, "Risparmio", 'Lista Movimenti'!$D:$D, ">=01/09/2026", 'Lista Movimenti'!$D:$D, "<=30/09/2026") -> 0 | K40: =SUMIFS('Lista Movimenti'!$C:$C, 'Lista Movimenti'!$B:$B, $A40, 'Lista Movimenti'!$E:$E, "Risparmio", 'Lista Movimenti'!$D:$D, ">=01/10/2026", 'Lista Movimenti'!$D:$D, "<=31/10/2026") -> 0 | L40: =SUMIFS('Lista Movimenti'!$C:$C, 'Lista Movimenti'!$B:$B, $A40, 'Lista Movimenti'!$E:$E, "Risparmio", 'Lista Movimenti'!$D:$D, ">=01/11/2026", 'Lista Movimenti'!$D:$D, "<=30/11/2026") -> 0 | M40: =SUMIFS('Lista Movimenti'!$C:$C, 'Lista Movimenti'!$B:$B, $A40, 'Lista Movimenti'!$E:$E, "Risparmio", 'Lista Movimenti'!$D:$D, ">=01/12/2026", 'Lista Movimenti'!$D:$D, "<=31/12/2026") -> 0 | N40: =AVERAGE(B40:M40) -> 0
A41: 🏋️ Palestra e affini | B41: =SUMIFS('Lista Movimenti'!C:C, 'Lista Movimenti'!B:B, A41, 'Lista Movimenti'!E:E, "Risparmio", 'Lista Movimenti'!D:D, ">=01/01/2026", 'Lista Movimenti'!D:D, "<=31/01/2026") -> 0 | C41: =SUMIFS('Lista Movimenti'!$C:$C, 'Lista Movimenti'!$B:$B, $A41, 'Lista Movimenti'!$E:$E, "Risparmio", 'Lista Movimenti'!$D:$D, ">=01/02/2026", 'Lista Movimenti'!$D:$D, "<=28/02/2026") -> 0 | D41: =SUMIFS('Lista Movimenti'!$C:$C, 'Lista Movimenti'!$B:$B, $A41, 'Lista Movimenti'!$E:$E, "Risparmio", 'Lista Movimenti'!$D:$D, ">=01/03/2026", 'Lista Movimenti'!$D:$D, "<=31/03/2026") -> 0 | E41: =SUMIFS('Lista Movimenti'!$C:$C, 'Lista Movimenti'!$B:$B, $A41, 'Lista Movimenti'!$E:$E, "Risparmio", 'Lista Movimenti'!$D:$D, ">=01/04/2026", 'Lista Movimenti'!$D:$D, "<=30/04/2026") -> 0 | F41: =SUMIFS('Lista Movimenti'!$C:$C, 'Lista Movimenti'!$B:$B, $A41, 'Lista Movimenti'!$E:$E, "Risparmio", 'Lista Movimenti'!$D:$D, ">=01/05/2026", 'Lista Movimenti'!$D:$D, "<=31/05/2026") -> 0 | G41: =SUMIFS('Lista Movimenti'!$C:$C, 'Lista Movimenti'!$B:$B, $A41, 'Lista Movimenti'!$E:$E, "Risparmio", 'Lista Movimenti'!$D:$D, ">=01/06/2026", 'Lista Movimenti'!$D:$D, "<=30/06/2026") -> 0 | H41: =SUMIFS('Lista Movimenti'!$C:$C, 'Lista Movimenti'!$B:$B, $A41, 'Lista Movimenti'!$E:$E, "Risparmio", 'Lista Movimenti'!$D:$D, ">=01/07/2026", 'Lista Movimenti'!$D:$D, "<=31/07/2026") -> 0 | I41: =SUMIFS('Lista Movimenti'!$C:$C, 'Lista Movimenti'!$B:$B, $A41, 'Lista Movimenti'!$E:$E, "Risparmio", 'Lista Movimenti'!$D:$D, ">=01/08/2026", 'Lista Movimenti'!$D:$D, "<=31/08/2026") -> 0 | J41: =SUMIFS('Lista Movimenti'!$C:$C, 'Lista Movimenti'!$B:$B, $A41, 'Lista Movimenti'!$E:$E, "Risparmio", 'Lista Movimenti'!$D:$D, ">=01/09/2026", 'Lista Movimenti'!$D:$D, "<=30/09/2026") -> 0 | K41: =SUMIFS('Lista Movimenti'!$C:$C, 'Lista Movimenti'!$B:$B, $A41, 'Lista Movimenti'!$E:$E, "Risparmio", 'Lista Movimenti'!$D:$D, ">=01/10/2026", 'Lista Movimenti'!$D:$D, "<=31/10/2026") -> 1500 | L41: =SUMIFS('Lista Movimenti'!$C:$C, 'Lista Movimenti'!$B:$B, $A41, 'Lista Movimenti'!$E:$E, "Risparmio", 'Lista Movimenti'!$D:$D, ">=01/11/2026", 'Lista Movimenti'!$D:$D, "<=30/11/2026") -> 0 | M41: =SUMIFS('Lista Movimenti'!$C:$C, 'Lista Movimenti'!$B:$B, $A41, 'Lista Movimenti'!$E:$E, "Risparmio", 'Lista Movimenti'!$D:$D, ">=01/12/2026", 'Lista Movimenti'!$D:$D, "<=31/12/2026") -> 0 | N41: =AVERAGE(B41:M41) -> 125
